Workbook

Sheet Summary
A1: Marketing Budget - Summary & Recommendation
A2: Top Tier Roofing & Remodeling - Albertville, Minnesota - prepared 2026-09-03
A4: The real question
A5: Nearly every job this company has done came from referral - a channel that costs about zero. The revenue base was built without buying customers. That is why a percent-of-revenue benchmark is a weak frame here: the 3-10% band describes companies that ACQUIRE through marketing, and this one never has to. So the question is not "what percent should we spend?" It is: what does it cost to build a second channel that does not depend on referrals? The three tiers below answer that at three levels of ambition.
A7: Three tiers - pick the ambition, the budget follows
A8: Tier | B8: New-work goal | C8: Jobs | D8: Leads | E8: Total budget | F8: % of revenue
A9: ='Goal Model'!A25 | B9: ='Goal Model'!B25 | C9: ='Goal Model'!C25 | D9: ='Goal Model'!D25 | E9: ='Goal Model'!G25 | F9: ='Goal Model'!H25
A10: ='Goal Model'!A26 | B10: ='Goal Model'!B26 | C10: ='Goal Model'!C26 | D10: ='Goal Model'!D26 | E10: ='Goal Model'!G26 | F10: ='Goal Model'!H26
A11: ='Goal Model'!A27 | B11: ='Goal Model'!B27 | C11: ='Goal Model'!C27 | D11: ='Goal Model'!D27 | E11: ='Goal Model'!G27 | F11: ='Goal Model'!H27
A12: Tier 2 is shaded as the recommended starting point: it is the first tier that builds a real second channel rather than just covering the current commitment, and it lands inside the range this trade recognizes. Every tier passes the affordable-cost-to-acquire test and sits inside the local market.
A14: Where you are now
A15: Marketing today (filed return) | B15: ='Current Spend'!B22 | C15: ='Current Spend'!B20
A16: Fixed / always-on already running | C16: ='Goal Model'!B11
A17: Selected tier budget | C17: ='Goal Model'!B39
A18: Net of co-op / rebates | C18: ='Goal Model'!B40
A20: Guardrails on every tier
A21: AFFORDABLE COST TO ACQUIRE: gross profit per job (~$1,790, straight off your return) is the ceiling on what a job may cost to win. Every tier is tested against it and every channel carries its own flag. LOCAL MARKET: each tier's lead requirement is checked against the ~35,000 roof-target universe, and the mail plan against the 1,433 addressed homes actually on the list. MEASURE TO REPLACE: the cost-per-lead prices are 90-day seeds; your Contractors Cloud lead-source field turns them into measured cost per job. PERCENT OF REVENUE IS AN OUTPUT here, reported after the fact - it is never used to set the number.
A23: Working figures. Edit the highlighted cells on the Goal Model, Channel Plan and Co-op tabs; everything here recalculates. Sources are on the Assumptions & Sources tab.

Sheet Goal Model
A1: Goal-Driven Model and the Three Tiers
A2: Pick an ambition. The spend is derived from your own economics; the % of revenue is only reported.
A4: INPUTS - edit the highlighted cells
A5: Annual revenue (2025 filed return) | B5: 1189873
A6: Gross profit (2025 filed return) | B6: 425875
A7: Average job value | B7: 5000
A8: Close rate (share of leads that become jobs) | B8: 0.25
A9: Target return (gross profit earned per $1 spent) | B9: 3
A10: Co-op / rebate offset (annual) | B10: ='Co-op & Rebates'!B7
A11: Fixed / always-on marketing (annual) | B11: ='Channel Plan'!B12
A12: Revenue and gross profit come straight off the 2025 return. Fixed / always-on cost is built on the Channel Plan from marketing vendors already on your card. Percent of revenue appears nowhere as an input.
A14: AFFORDABLE COST TO ACQUIRE - the ceiling comes from your margin
A15: Gross margin (= gross profit / revenue) | B15: =B6/B5
A16: Gross profit per job (= job value x margin) | B16: =B7*B15
A17: Leads per job (= 1 / close rate) | B17: =1/B8
A18: Breakeven cost per lead (absolute ceiling) | B18: =B16/B17
A19: Target max cost per job (= gross profit / target return) | B19: =B16/B9
A20: Target max cost per lead | B20: =B19/B17
A21: Gross profit per job is the most you could ever pay to win a job and still break even. Every tier and every channel below is tested against it.
A23: THE THREE TIERS - ambition drives the spend; the % of revenue is the result
A24: Tier | B24: New-work goal | C24: Jobs | D24: Leads | E24: Variable spend | F24: Fixed / always-on | G24: TOTAL BUDGET | H24: % of revenue | I24: Cost per job | J24: Vs affordable CAC | K24: Vs local market
A25: 1 - Hit the commitment | B25: 150000 | C25: =B25/$B$7 | D25: =C25*$B$17 | E25: =D25*$B$20 | F25: =$B$11 | G25: =E25+F25 | H25: =G25/$B$5 | I25: =G25/C25 | J25: =IF(I25<=$B$16,"PASS","FAIL - above breakeven") | K25: =IF(D25<=$B$33,"PASS","FAIL - exceeds local universe")
A26: 2 - Real growth | B26: 400000 | C26: =B26/$B$7 | D26: =C26*$B$17 | E26: =D26*$B$20 | F26: =$B$11 | G26: =E26+F26 | H26: =G26/$B$5 | I26: =G26/C26 | J26: =IF(I26<=$B$16,"PASS","FAIL - above breakeven") | K26: =IF(D26<=$B$33,"PASS","FAIL - exceeds local universe")
A27: 3 - Aggressive | B27: 750000 | C27: =B27/$B$7 | D27: =C27*$B$17 | E27: =D27*$B$20 | F27: =$B$11 | G27: =E27+F27 | H27: =G27/$B$5 | I27: =G27/C27 | J27: =IF(I27<=$B$16,"PASS","FAIL - above breakeven") | K27: =IF(D27<=$B$33,"PASS","FAIL - exceeds local universe")
A28: Edit the New-work goal on any tier and everything to its right recalculates. Variable spend is the leads that goal needs, priced at your target cost per lead; fixed / always-on is added on top. Nothing here is set by choosing a percentage.
A30: LOCAL MARKET CEILING
A31: Roof-target universe (counties already pulled) | B31: 35000
A32: Max plausible annual penetration | B32: 0.05
A33: Max plausible annual leads (universe x penetration) | B33: =B31*B32
A34: Each tier's lead requirement is checked against this ceiling in the table above. The mail-specific capacity check sits on the Channel Plan.
A35: SELECTED TIER - drives the Channel Plan
A36: Selected tier (1, 2 or 3) | B36: 2
A37: Tier name | B37: =INDEX(A25:A27,B36)
A38: Leads required | B38: =INDEX(D25:D27,B36)
A39: Total budget | B39: =INDEX(G25:G27,B36)
A40: Net of co-op / rebate offset | B40: =B39-B10

Sheet Channel Plan
A1: Channel Plan - fixed, lumpy and variable
A2: Always-on cost is separated from lead buying. Mail is priced per piece, not per lead.
A4: A. FIXED / ALWAYS-ON - runs whether or not you buy a lead
A5: Item | B5: Annual cost | D5: Leads attributed | I5: Basis / source
A6: Website & digital vendor (Apex Media Solutions) | B6: ='Current Spend'!B6/2 | I6: 24-month card spend, annualized
A7: Better Business Bureau membership | B7: ='Current Spend'!B9/2 | I7: 24-month card spend, annualized; bills monthly
A8: Direct-mail platform tooling (Dope Marketing) | B8: ='Current Spend'!B8/2 | I8: 24-month card spend, annualized; the platform, not the postage
A9: Other named marketing vendors | B9: =('Current Spend'!B11+'Current Spend'!B12+'Current Spend'!B13)/2 | I9: LPI Digital, Welcome Wagon, Brandefined - annualized
A10: Additional always-on (website / GBP management) | B10: 0 | I10: No dedicated line exists on the card today. Enter one if you retain this work.
A11: Google Business Profile / organic (no media cost) | B11: 0 | D11: 40 | I11: Leads attributed are a planning estimate driven by the review habit (3 reviews = 1 lead).
A12: Total fixed / always-on | B12: =SUM(B6:B11) | D12: =SUM(D6:D11)
A14: B. LUMPY CHANNELS - the drop costs what it costs; response rate decides the yield
A15: Channel | B15: Pieces per drop | C15: Cost per piece | D15: Drops per year | E15: Response rate | F15: Annual cost | G15: Leads per year | H15: Implied cost per lead | I15: Vs affordable CAC
A16: Direct mail (addressed prospect list) | B16: 1433 | C16: 0.85 | D16: 3 | E16: 0.01 | F16: =B16*C16*D16 | G16: =B16*E16*D16 | H16: =IF(G16=0,0,F16/G16) | I16: =IF(H16<='Goal Model'!$B$20,"OK",IF(H16<='Goal Model'!$B$18,"CAUTION - above target","STOP - above breakeven"))
A17: Repeat-touch drip (past customers, house list) | B17: 300 | C17: 0.85 | D17: 4 | E17: 0.03 | F17: =B17*C17*D17 | G17: =B17*E17*D17 | H17: =IF(G17=0,0,F17/G17) | I17: =IF(H17<='Goal Model'!$B$20,"OK",IF(H17<='Goal Model'!$B$18,"CAUTION - above target","STOP - above breakeven"))
A18: Total lumpy | F18: =SUM(F16:F17) | G18: =SUM(G16:G17) | H18: =IF(G18=0,0,F18/G18)
A19: Cost per lead here is an OUTPUT, not a price you pay. It is simply cost per piece divided by response rate: at 1.0% response an $0.85 piece yields an $85 lead; at 0.5% the same drop yields a $170 lead. The drop costs the same either way - that is what makes it lumpy.
A21: C. VARIABLE CHANNELS - auction-priced, you buy leads one at a time
A22: Channel | B22: Market cost per lead | C22: Planned annual spend | D22: Planned leads | H22: Vs affordable CAC
A23: Local Services Ads (LSA) | B23: 150 | C23: 18000 | D23: =IF(B23=0,0,C23/B23) | H23: =IF(B23<='Goal Model'!$B$20,"OK",IF(B23<='Goal Model'!$B$18,"CAUTION - above target","STOP - above breakeven"))
A24: Facebook / Meta | B24: 100 | C24: 12000 | D24: =IF(B24=0,0,C24/B24) | H24: =IF(B24<='Goal Model'!$B$20,"OK",IF(B24<='Goal Model'!$B$18,"CAUTION - above target","STOP - above breakeven"))
A25: Referral program (thank-you / rewards) | B25: 50 | C25: 1500 | D25: =IF(B25=0,0,C25/B25) | H25: =IF(B25<='Goal Model'!$B$20,"OK",IF(B25<='Goal Model'!$B$18,"CAUTION - above target","STOP - above breakeven"))
A26: Total variable | B26: =IF(D26=0,0,C26/D26) | C26: =SUM(C23:C25) | D26: =SUM(D23:D25)
A28: D. PLAN TOTAL vs THE SELECTED TIER
A29: Total planned spend (fixed + lumpy + variable) | B29: =B12+F18+C26
A30: Total planned leads | B30: =D12+G18+D26
A31: Implied jobs | B31: =B30*'Goal Model'!B8
A32: Implied new-work revenue | B32: =B31*'Goal Model'!B7
A33: Blended cost per lead | B33: =IF(B30=0,0,B29/B30)
A34: Implied cost per job | B34: =IF(B31=0,0,B29/B31)
A35: Cost per job vs affordable ceiling | B35: =IF(B34<='Goal Model'!B16,"PASS - under breakeven","FAIL - above breakeven")
A36: Selected tier | B36: ='Goal Model'!B37
A37: Tier leads required | B37: ='Goal Model'!B38
A38: Tier budget | B38: ='Goal Model'!B39
A39: Leads check | B39: =IF(B30>=B37,"meets the tier","SHORT of the tier")
A40: Budget check | B40: =IF(B29<=B38,"within tier budget","OVER tier budget")
A42: E. LOCAL MARKET CEILING
A43: Addressed mailable homes (current list) | B43: =B16
A44: Max plausible response rate (prospect list) | B44: 0.05
A45: Max plausible mail leads per year | B45: =B43*B44*D16
...

Sheet Current Spend
A1: Current Marketing Spend
A2: Named vendors from 24 months of company-card charges. The always-on section of the Channel Plan is built from these.
A4: Named marketing vendors - 24 months of company-card charges
A5: Vendor | B5: Paid (24 mo) | C5: Classification | D5: Action | E5: Note
A6: Apex Media Solutions LLC | B6: 4960 | C6: Marketing | D6: Keep - always-on | E6: Website / digital vendor; largest marketing vendor on the card.
A7: HailTrace | B7: 2260 | C7: Operations | D7: Reclass out | E7: Storm / hail intelligence tool -> Operations, not marketing.
A8: Dope Marketing | B8: 2039 | C8: Marketing | D8: Keep - always-on | E8: Direct-mail platform; the tooling, not the postage.
A9: Better Business Bureau | B9: 1230 | C9: Marketing | D9: Keep - always-on | E9: Membership; the only line that bills every month.
A10: Pothos Advertising | B10: 1210 | C10: IT | D10: Reclass out | E10: Reclassified to IT in prior analysis, not marketing.
A11: LPI Digital LLC | B11: 414 | C11: Marketing | D11: Review | E11: Single charge; confirm scope and whether still active.
A12: Welcome Wagon | B12: 336.96 | C12: Marketing | D12: Review | E12: New-mover direct mail; single charge.
A13: Brandefined | B13: 64.7 | C13: Marketing | D13: Review | E13: Most recent marketing charge on the card.
A14: Total named marketing (card, 24 mo) | B14: =SUM(B6:B13)
A15: Less: reclassified to Operations / IT | B15: =-(B7+B10)
A16: Net named marketing (card, 24 mo) | B16: =B14+B15
A17: Annualized (= net / 2) | B17: =B16/2
A19: Current marketing as a share of revenue
A20: Filed return - annual advertising line | B20: 11412
A21: Revenue (most recent filed year) | B21: ='Goal Model'!B5
A22: Advertising as % of revenue | B22: =B20/B21
A24: The card census spans 24 months and misses anything paid by check or another card. The filed return's annual advertising line ($11,412 = 0.96% of revenue) is the authoritative current figure.

Sheet Co-op & Rebates
A1: Co-op & Rebates
A2: Offsets that reduce out-of-pocket marketing spend. Enter amounts as they are confirmed.
A4: Offsets - edit the highlighted cells
A5: Owens Corning co-op (annual) | B5: 0 | C5: Pending - Guy is confirming the amount with the rep. Enter it here when known; leave 0 until then.
A6: Supplier / manufacturer rebates (annual) | B6: 0 | C6: Enter any confirmed supplier rebate that offsets marketing.
A7: Total offsets | B7: =B5+B6
A9: Effect on the selected tier
A10: Selected tier budget (gross) | B10: ='Goal Model'!B39
A11: Less: total offsets | B11: =B7
A12: Net out-of-pocket | B12: =B10-B11
A14: No co-op figure has been invented. The offset defaults to 0 and flows into the Goal Model and Summary the moment a real number is entered above.

Sheet Assumptions & Sources
A1: Assumptions & Sources
A2: How the model is built, every seeded price, and the citations.
A4: METHOD: Ambition drives the spend. You choose what to achieve; the budget is derived from your own economics and the resulting percent of revenue is only reported back to you -- it is never an input. Every number driving a tier traces to the 2025 filed return or to your own pulled market. External data is confined to input prices and response rates, labeled as 90-day seeds to be replaced by measured Contractors Cloud lead-source data. No industry ROI figure is used anywhere.
A5: Item | B5: Value | C5: Source / basis
A6: Annual revenue | B6: $1,189,873 | C6: YOUR BOOKS. 2025 filed return, gross receipts.
A7: Gross profit / margin | B7: $425,875 / 35.79% | C7: YOUR BOOKS. 2025 filed return (Form 1125-A). Matches the owners' stated ~33%.
A8: Average job value | B8: $5,000 | C8: YOUR TARGET. $150,000 of new work at ~$5,000/job = ~30 jobs (Tier 1).
A9: Gross profit per job | B9: ~$1,790 | C9: DERIVED. $5,000 x 35.79%. The breakeven cost to acquire a job; the ceiling on every tier.
A10: The card's $4,000 / $5,000 | B10: job VALUE, not profit | C10: CLARIFIED. That figure is revenue per job, not gross profit. Acquisition math uses the margin-derived $1,790.
A11: Close rate | B11: 25% (4 leads = 1 job) | C11: YOUR WORKING ASSUMPTION. Editable; the wall also carries a 50% reading.
A12: Target return | B12: 3.0 : 1 | C12: YOUR CHOICE. $3 of gross profit per $1 spent; sets the target (not breakeven) cost per lead.
A13: Tier goals | B13: $150k / $400k / $750k | C13: YOUR CHOICE. Tier 3 lands the business near the $2M the owners have talked about.
A14: Current advertising spend | B14: $11,412 = 0.96% of revenue | C14: YOUR BOOKS. 2025 filed return advertising line.
A15: Named vendor card spend | B15: $12,514.66 / 8 vendors (24 mo) | C15: YOUR BOOKS. HailTrace -> Operations and Pothos -> IT reclassified out; net $9,044.66, annualized $4,522.
A16: Fixed / always-on cost | B16: ~$4,522 per year | C16: YOUR BOOKS. Built only from marketing vendors already on the card, annualized. Nothing invented.
... A26: Owens Corning co-op | B26: $0 (pending) | C26: NOT INVENTED. Defaults to 0 until the confirmed amount is entered on the Co-op tab.
A28: Why mail is modeled differently
A29: A mail drop is not bought one lead at a time. Printing and posting 1,433 pieces costs the same whether it returns eight leads or twenty-eight. So mail is modeled as pieces x cost per piece x drops, with a response rate deriving the leads, and the cost per lead falls out as a RESULT. That result is simply cost per piece divided by response rate -- which is why response rate, not price per piece, is the number worth managing. Halving the response doubles the cost per lead for an identical print and postage bill.
A31: What a lead and a review are worth
A32: On your own economics a lead is worth up to its breakeven cost -- gross profit per job divided by leads per job (~$1,790 / 4 = ~$447) -- and a review about a third of that (3 reviews = 1 lead, ~$149). Separately, the UDE work assigns a review a strategic value of $800; that rests on more optimistic inputs and lives in that deliverable. This budget uses the conservative margin-derived ceiling for what you can afford to PAY; the $800 is a strategic value, not a spend ceiling.
A34: How to make this a living worksheet
A35: 1. Every highlighted cell is editable. 2. Change a tier's new-work goal, the close rate, the target return, a response rate or any cost per lead and the Summary, Goal Model and Channel Plan all update. 3. Set the Selected tier cell to 1, 2 or 3 to re-point the Channel Plan. 4. Over ~90 days, replace the market cost-per-lead seeds with your own cost / total_used from the Contractors Cloud lead-source field. 5. Enter the Owens Corning co-op amount on the Co-op tab when confirmed.
